<?xml version="1.0" encoding="utf-8"?>
 <!-- This URDF was automatically created by SolidWorks to URDF Exporter! Originally created by Stephen Brawner (brawner@gmail.com) 
      Commit Version: 1.6.0-4-g7f85cfe  Build Version: 1.6.7995.38578
      For more information, please see http://wiki.ros.org/sw_urdf_exporter -->
 <robot name="HTDW_4438">
  <mujoco>
    <compiler meshdir="../meshes/" balanceinertia="true" discardvisual="false" />
  </mujoco>

   <link name="base_link">
     <inertial>
       <origin xyz="-0.00150909 -0.00098889 0.00305206" rpy="0 0 0" />
       <mass value="2.38259971" />
       <inertia ixx="0.00432585" ixy="-1.251e-05" ixz="0.00022699" iyy="0.00844472" iyz="2.196e-05" izz="0.00822046" />
     </inertial>
     <visual>
       <origin xyz="0 0 0" rpy="0 0 0" />
       <geometry>
         <mesh filename="../meshes/base_link.STL" />
       </geometry>
       <material name="">
         <color rgba="0.752941176470588 0.752941176470588 0.752941176470588 1" />
       </material>
     </visual>
     <collision>
       <origin xyz="0 0 0" rpy="0 0 0" />
       <geometry>
         <mesh filename="../meshes/base_link.STL" />
       </geometry>
     </collision>
   </link>
   <link name="FL_hip">
     <inertial>
       <origin xyz="-0.00110429 -9.855e-05 -0.000137" rpy="0 0 0" />
       <mass value="0.25169471" />
       <inertia ixx="3.845e-05" ixy="1.34e-06" ixz="-2.6e-07" iyy="4.547e-05" iyz="9.6e-07" izz="4.418e-05" />
     </inertial>
     <visual>
       <origin xyz="0 0 0" rpy="0 0 0" />
       <geometry>
         <mesh filename="../meshes/FL_hip.STL" />
       </geometry>
       <material name="">
         <color rgba="0.752941176470588 0.752941176470588 0.752941176470588 1" />
       </material>
     </visual>
     <collision>
       <origin xyz="0 0 0" rpy="0 0 0" />
       <geometry>
         <mesh filename="../meshes/FL_hip.STL" />
       </geometry>
     </collision>
   </link>
   <joint name="FL_hip_joint" type="revolute">
     <origin xyz="0.11415 0.035 -0.0085" rpy="0 0 0" />
     <parent link="base_link" />
     <child link="FL_hip" />
     <axis xyz="1 0 0" />
     <limit lower="-1.05" upper="1.05" effort="10" velocity="9.5" />
   </joint>
   <link name="FL_thigh">
     <inertial>
       <origin xyz="-0.00114943 -0.02533574 -0.0099421" rpy="0 0 0" />
       <mass value="0.34225574" />
       <inertia ixx="0.00044342" ixy="7.17e-06" ixz="-1.819e-05" iyy="0.0003823" iyz="8.294e-05" izz="0.00013666" />
     </inertial>
     <visual>
       <origin xyz="0 0 0" rpy="0 0 0" />
       <geometry>
         <mesh filename="../meshes/FL_thigh.STL" />
       </geometry>
       <material name="">
         <color rgba="0.752941176470588 0.752941176470588 0.752941176470588 1" />
       </material>
     </visual>
     <collision>
       <origin xyz="0 0 0" rpy="0 0 0" />
       <geometry>
         <mesh filename="../meshes/FL_thigh.STL" />
       </geometry>
     </collision>
   </link>
   <joint name="FL_thigh_joint" type="revolute">
     <origin xyz="0 0.0812 0" rpy="0 0 0" />
     <parent link="FL_hip" />
     <child link="FL_thigh" />
     <axis xyz="0 1 0" />
     <limit lower="-1.57" upper="3.49" effort="10" velocity="9.5" />
   </joint>
   <link name="FL_calf">
     <inertial>
       <origin xyz="0.00873361 1.881e-05 -0.05124231" rpy="0 0 0" />
       <mass value="0.03063479" />
       <inertia ixx="6.529e-05" ixy="0.0" ixz="9.5e-07" iyy="6.662e-05" iyz="-4e-08" izz="2.3e-06" />
     </inertial>
     <visual>
       <origin xyz="0 0 0" rpy="0 0 0" />
       <geometry>
         <mesh filename="../meshes/FL_calf.STL" />
       </geometry>
       <material name="">
         <color rgba="0.752941176470588 0.752941176470588 0.752941176470588 1" />
       </material>
     </visual>
     <collision>
       <origin xyz="0 0 0" rpy="0 0 0" />
       <geometry>
         <mesh filename="../meshes/FL_calf.STL" />
       </geometry>
     </collision>
   </link>
   <joint name="FL_calf_joint" type="revolute">
     <origin xyz="0 0 -0.12" rpy="0 0 0" />
     <parent link="FL_thigh" />
     <child link="FL_calf" />
     <axis xyz="0 1 0" />
     <limit lower="-2.71" upper="-0.84" effort="10" velocity="9.5" />
   </joint>
   <link name="FL_foot">
     <inertial>
       <origin xyz="-0.00180864 0.0 -0.00401616" rpy="0 0 0" />
       <mass value="0.00959044" />
       <inertia ixx="8.2e-07" ixy="0.0" ixz="1.4e-07" iyy="1.06e-06" iyz="0.0" izz="1.03e-06" />
     </inertial>
     <visual>
       <origin xyz="0 0 0" rpy="0 0 0" />
       <geometry>
         <mesh filename="../meshes/FL_foot.STL" />
       </geometry>
       <material name="">
         <color rgba="0.298039215686275 0.298039215686275 0.298039215686275 1" />
       </material>
     </visual>
     <collision>
       <origin xyz="0 0 0" rpy="0 0 0" />
       <geometry>
         <sphere radius="0.01675"/>
       </geometry>
     </collision>
   </link>
   <joint name="FL_foot_joint" type="fixed">
     <origin xyz="0 0 -0.12516" rpy="0 0 0" />
     <parent link="FL_calf" />
     <child link="FL_foot" />
     <axis xyz="0 0 0" />
   </joint>
   <link name="FR_hip">
     <inertial>
       <origin xyz="-0.00127689 9.855e-05 -0.000137" rpy="0 0 0" />
       <mass value="0.25169471" />
       <inertia ixx="3.845e-05" ixy="-1.26e-06" ixz="-6.3e-07" iyy="4.536e-05" iyz="-9.6e-07" izz="4.408e-05" />
     </inertial>
     <visual>
       <origin xyz="0 0 0" rpy="0 0 0" />
       <geometry>
         <mesh filename="../meshes/FR_hip.STL" />
       </geometry>
       <material name="">
         <color rgba="0.752941176470588 0.752941176470588 0.752941176470588 1" />
       </material>
     </visual>
     <collision>
       <origin xyz="0 0 0" rpy="0 0 0" />
       <geometry>
         <mesh filename="../meshes/FR_hip.STL" />
       </geometry>
     </collision>
   </link>
   <joint name="FR_hip_joint" type="revolute">
     <origin xyz="0.11415 -0.035 -0.0085" rpy="0 0 0" />
     <parent link="base_link" />
     <child link="FR_hip" />
     <axis xyz="1 0 0" />
     <limit lower="-1.05" upper="1.05" effort="10" velocity="9.5" />
   </joint>
   <link name="FR_thigh">
     <inertial>
       <origin xyz="-0.00124929 0.02533762 -0.01012479" rpy="0 0 0" />
       <mass value="0.34223842" />
       <inertia ixx="0.00044215" ixy="-7.36e-06" ixz="-1.777e-05" iyy="0.00038093" iyz="-8.33e-05" izz="0.0001365" />
     </inertial>
     <visual>
       <origin xyz="0 0 0" rpy="0 0 0" />
       <geometry>
         <mesh filename="../meshes/FR_thigh.STL" />
       </geometry>
       <material name="">
         <color rgba="0.752941176470588 0.752941176470588 0.752941176470588 1" />
       </material>
     </visual>
     <collision>
       <origin xyz="0 0 0" rpy="0 0 0" />
       <geometry>
         <mesh filename="../meshes/FR_thigh.STL" />
       </geometry>
     </collision>
   </link>
   <joint name="FR_thigh_joint" type="revolute">
     <origin xyz="0 -0.0812 0" rpy="0 0 0" />
     <parent link="FR_hip" />
     <child link="FR_thigh" />
     <axis xyz="0 1 0" />
     <limit lower="-1.57" upper="3.49" effort="10" velocity="9.5" />
   </joint>
   <link name="FR_calf">
     <inertial>
       <origin xyz="0.00873361 -2.058e-05 -0.05124231" rpy="0 0 0" />
       <mass value="0.03063479" />
       <inertia ixx="6.529e-05" ixy="0.0" ixz="9.5e-07" iyy="6.662e-05" iyz="4e-08" izz="2.3e-06" />
     </inertial>
     <visual>
       <origin xyz="0 0 0" rpy="0 0 0" />
       <geometry>
         <mesh filename="../meshes/FR_calf.STL" />
       </geometry>
       <material name="">
         <color rgba="0.752941176470588 0.752941176470588 0.752941176470588 1" />
       </material>
     </visual>
     <collision>
       <origin xyz="0 0 0" rpy="0 0 0" />
       <geometry>
         <mesh filename="../meshes/FR_calf.STL" />
       </geometry>
     </collision>
   </link>
   <joint name="FR_calf_joint" type="revolute">
     <origin xyz="0 0 -0.12" rpy="0 0 0" />
     <parent link="FR_thigh" />
     <child link="FR_calf" />
     <axis xyz="0 1 0" />
     <limit lower="-2.71" upper="-0.84" effort="10" velocity="9.5" />
   </joint>
   <link name="FR_foot">
     <inertial>
       <origin xyz="-0.00180864 0.0 -0.00401616" rpy="0 0 0" />
       <mass value="0.00959044" />
       <inertia ixx="8.2e-07" ixy="0.0" ixz="1.4e-07" iyy="1.06e-06" iyz="0.0" izz="1.03e-06" />
     </inertial>
     <visual>
       <origin xyz="0 0 0" rpy="0 0 0" />
       <geometry>
         <mesh filename="../meshes/FR_foot.STL" />
       </geometry>
       <material name="">
         <color rgba="0.298039215686275 0.298039215686275 0.298039215686275 1" />
       </material>
     </visual>
     <collision>
       <origin xyz="0 0 0" rpy="0 0 0" />
       <geometry>
         <sphere radius="0.01675"/>
       </geometry>
     </collision>
   </link>
   <joint name="FR_foot_joint" type="fixed">
     <origin xyz="0 0 -0.12516" rpy="0 0 0" />
     <parent link="FR_calf" />
     <child link="FR_foot" />
     <axis xyz="0 0 0" />
   </joint>
   <link name="RL_hip">
     <inertial>
       <origin xyz="0.00127689 -9.855e-05 -0.000137" rpy="0 0 0" />
       <mass value="0.25169471" />
       <inertia ixx="3.845e-05" ixy="-1.26e-06" ixz="6.3e-07" iyy="4.536e-05" iyz="9.6e-07" izz="4.408e-05" />
     </inertial>
     <visual>
       <origin xyz="0 0 0" rpy="0 0 0" />
       <geometry>
         <mesh filename="../meshes/RL_hip.STL" />
       </geometry>
       <material name="">
         <color rgba="0.752941176470588 0.752941176470588 0.752941176470588 1" />
       </material>
     </visual>
     <collision>
       <origin xyz="0 0 0" rpy="0 0 0" />
       <geometry>
         <mesh filename="../meshes/RL_hip.STL" />
       </geometry>
     </collision>
   </link>
   <joint name="RL_hip_joint" type="revolute">
     <origin xyz="-0.11415 0.035 -0.0085" rpy="0 0 0" />
     <parent link="base_link" />
     <child link="RL_hip" />
     <axis xyz="1 0 0" />
     <limit lower="-1.05" upper="1.05" effort="10" velocity="9.5" />
   </joint>
   <link name="RL_thigh">
     <inertial>
       <origin xyz="-0.00114943 -0.02533574 -0.0099421" rpy="0 0 0" />
       <mass value="0.34225574" />
       <inertia ixx="0.00044342" ixy="7.17e-06" ixz="-1.819e-05" iyy="0.0003823" iyz="8.294e-05" izz="0.00013666" />
     </inertial>
     <visual>
       <origin xyz="0 0 0" rpy="0 0 0" />
       <geometry>
         <mesh filename="../meshes/RL_thigh.STL" />
       </geometry>
       <material name="">
         <color rgba="0.752941176470588 0.752941176470588 0.752941176470588 1" />
       </material>
     </visual>
     <collision>
       <origin xyz="0 0 0" rpy="0 0 0" />
       <geometry>
         <mesh filename="../meshes/RL_thigh.STL" />
       </geometry>
     </collision>
   </link>
   <joint name="RL_thigh_joint" type="revolute">
     <origin xyz="0 0.0812 0" rpy="0 0 0" />
     <parent link="RL_hip" />
     <child link="RL_thigh" />
     <axis xyz="0 1 0" />
     <limit lower="-1.57" upper="3.49" effort="10" velocity="9.5" />
   </joint>
   <link name="RL_calf">
     <inertial>
       <origin xyz="0.00873361 1.881e-05 -0.05124231" rpy="0 0 0" />
       <mass value="0.03063479" />
       <inertia ixx="6.529e-05" ixy="0.0" ixz="9.5e-07" iyy="6.662e-05" iyz="-4e-08" izz="2.3e-06" />
     </inertial>
     <visual>
       <origin xyz="0 0 0" rpy="0 0 0" />
       <geometry>
         <mesh filename="../meshes/RL_calf.STL" />
       </geometry>
       <material name="">
         <color rgba="0.752941176470588 0.752941176470588 0.752941176470588 1" />
       </material>
     </visual>
     <collision>
       <origin xyz="0 0 0" rpy="0 0 0" />
       <geometry>
         <mesh filename="../meshes/RL_calf.STL" />
       </geometry>
     </collision>
   </link>
   <joint name="RL_calf_joint" type="revolute">
     <origin xyz="0 0 -0.12" rpy="0 0 0" />
     <parent link="RL_thigh" />
     <child link="RL_calf" />
     <axis xyz="0 1 0" />
     <limit lower="-2.71" upper="-0.84" effort="10" velocity="9.5" />
   </joint>
   <link name="RL_foot">
     <inertial>
       <origin xyz="-0.00180864 0.0 -0.00401616" rpy="0 0 0" />
       <mass value="0.00959044" />
       <inertia ixx="8.2e-07" ixy="0.0" ixz="1.4e-07" iyy="1.06e-06" iyz="0.0" izz="1.03e-06" />
     </inertial>
     <visual>
       <origin xyz="0 0 0" rpy="0 0 0" />
       <geometry>
         <mesh filename="../meshes/RL_foot.STL" />
       </geometry>
       <material name="">
         <color rgba="0.298039215686275 0.298039215686275 0.298039215686275 1" />
       </material>
     </visual>
     <collision>
       <origin xyz="0 0 0" rpy="0 0 0" />
       <geometry>
         <sphere radius="0.01675"/>
       </geometry>
     </collision>
   </link>
   <joint name="RL_foot_joint" type="fixed">
     <origin xyz="0 0 -0.12516" rpy="0 0 0" />
     <parent link="RL_calf" />
     <child link="RL_foot" />
     <axis xyz="0 0 0" />
   </joint>
   <link name="RR_hip">
     <inertial>
       <origin xyz="0.00110429 9.855e-05 -0.000137" rpy="0 0 0" />
       <mass value="0.25169471" />
       <inertia ixx="3.845e-05" ixy="1.34e-06" ixz="2.6e-07" iyy="4.547e-05" iyz="-9.6e-07" izz="4.418e-05" />
     </inertial>
     <visual>
       <origin xyz="0 0 0" rpy="0 0 0" />
       <geometry>
         <mesh filename="../meshes/RR_hip.STL" />
       </geometry>
       <material name="">
         <color rgba="0.752941176470588 0.752941176470588 0.752941176470588 1" />
       </material>
     </visual>
     <collision>
       <origin xyz="0 0 0" rpy="0 0 0" />
       <geometry>
         <mesh filename="../meshes/RR_hip.STL" />
       </geometry>
     </collision>
   </link>
   <joint name="RR_hip_joint" type="revolute">
     <origin xyz="-0.11415 -0.035 -0.0085" rpy="0 0 0" />
     <parent link="base_link" />
     <child link="RR_hip" />
     <axis xyz="1 0 0" />
     <limit lower="-1.05" upper="1.05" effort="10" velocity="9.5" />
   </joint>
   <link name="RR_thigh">
     <inertial>
       <origin xyz="-0.00124929 0.02533762 -0.01012479" rpy="0 0 0" />
       <mass value="0.34223842" />
       <inertia ixx="0.00044215" ixy="-7.36e-06" ixz="-1.777e-05" iyy="0.00038093" iyz="-8.33e-05" izz="0.0001365" />
     </inertial>
     <visual>
       <origin xyz="0 0 0" rpy="0 0 0" />
       <geometry>
         <mesh filename="../meshes/RR_thigh.STL" />
       </geometry>
       <material name="">
         <color rgba="0.752941176470588 0.752941176470588 0.752941176470588 1" />
       </material>
     </visual>
     <collision>
       <origin xyz="0 0 0" rpy="0 0 0" />
       <geometry>
         <mesh filename="../meshes/RR_thigh.STL" />
       </geometry>
     </collision>
   </link>
   <joint name="RR_thigh_joint" type="revolute">
     <origin xyz="0 -0.0812 0" rpy="0 0 0" />
     <parent link="RR_hip" />
     <child link="RR_thigh" />
     <axis xyz="0 1 0" />
     <limit lower="-1.57" upper="3.49" effort="10" velocity="9.5" />
   </joint>
   <link name="RR_calf">
     <inertial>
       <origin xyz="0.00873361 -2.058e-05 -0.05124231" rpy="0 0 0" />
       <mass value="0.03063479" />
       <inertia ixx="6.529e-05" ixy="0.0" ixz="9.5e-07" iyy="6.662e-05" iyz="4e-08" izz="2.3e-06" />
     </inertial>
     <visual>
       <origin xyz="0 0 0" rpy="0 0 0" />
       <geometry>
         <mesh filename="../meshes/RR_calf.STL" />
       </geometry>
       <material name="">
         <color rgba="0.752941176470588 0.752941176470588 0.752941176470588 1" />
       </material>
     </visual>
     <collision>
       <origin xyz="0 0 0" rpy="0 0 0" />
       <geometry>
         <mesh filename="../meshes/RR_calf.STL" />
       </geometry>
     </collision>
   </link>
   <joint name="RR_calf_joint" type="revolute">
     <origin xyz="0 0 -0.12" rpy="0 0 0" />
     <parent link="RR_thigh" />
     <child link="RR_calf" />
     <axis xyz="0 1 0" />
     <limit lower="-2.71" upper="-0.84" effort="10" velocity="9.5" />
   </joint>
   <link name="RR_foot">
     <inertial>
       <origin xyz="-0.00180864 0.0 -0.00401616" rpy="0 0 0" />
       <mass value="0.00959044" />
       <inertia ixx="8.2e-07" ixy="0.0" ixz="1.4e-07" iyy="1.06e-06" iyz="0.0" izz="1.03e-06" />
     </inertial>
     <visual>
       <origin xyz="0 0 0" rpy="0 0 0" />
       <geometry>
         <mesh filename="../meshes/RR_foot.STL" />
       </geometry>
       <material name="">
         <color rgba="0.298039215686275 0.298039215686275 0.298039215686275 1" />
       </material>
     </visual>
     <collision>
       <origin xyz="0 0 0" rpy="0 0 0" />
       <geometry>
         <sphere radius="0.01675"/>
       </geometry>
     </collision>
   </link>
   <joint name="RR_foot_joint" type="fixed">
     <origin xyz="0 0 -0.12516" rpy="0 0 0" />
     <parent link="RR_calf" />
     <child link="RR_foot" />
     <axis xyz="0 0 0" />
   </joint>
 </robot>