<mujoco model="xqrobotV2">
  <default>
    <default class="robot">
      <joint damping="0.5" armature="0.002" frictionloss="0.01" />
      <default class="visual">
        <geom contype="0" conaffinity="0" group="2" />
      </default>
      <default class="collision">
        <geom contype="0" conaffinity="1" group="3" />
      </default>
    </default>
  </default>
  <compiler angle="radian" meshdir="assets" balanceinertia="true" />
  <worldbody>
    <body name="base_link" childclass="robot" pos="0 0 0.5022">
      <inertial pos="0 0 0" mass="5.0" diaginertia="0.1 0.1 0.1" />
      <site name="imu_in_base" size="0.01" />
      <geom name="base_link_collision" type="mesh" mesh="base_link_collision_base_link" class="collision" />
      <geom name="base_link_visual" type="mesh" mesh="base_link_base_link" class="visual" />
      <body name="left_link_1" pos="0.068989065886231 -0.123883478847315 -0.000994304172399263">
        <inertial pos="-0.0329313 -0.0106322 0.0002716" mass="0.17414594" diaginertia="9.79354e-05 0.00018457 0.0001347" />
        <joint name="left_joint_1" type="hinge" range="-3.141592653589793 3.141592653589793" axis="1 0 0" />
        <geom name="left_link_1_collision" type="mesh" mesh="left_link_1_collision_left_link_1" class="collision" />
        <geom name="left_link_1_visual" type="mesh" mesh="left_link_1_left_link_1" class="visual" />
        <body name="left_link_2" pos="-0.0698 -0.019497832506859 0.00029073619393083">
          <inertial pos="-0.1067452 0.0104288 -0.0754200" mass="0.67262843" diaginertia="0.00196263 0.00341763 0.00227239" />
          <joint name="left_joint_2" type="hinge" range="0 2.0943951023931953" axis="0 1 0" />
          <geom name="left_link_2_collision" type="mesh" mesh="left_link_2_collision_left_link_2" class="collision" />
          <geom name="left_link_2_visual" type="mesh" mesh="left_link_2_left_link_2" class="visual" />
          <body name="left_link_3" pos="-0.223606797749979 0.0150160895557946 -0.200246141172439">
            <inertial pos="0.0949942 -0.0011798 -0.0810423" mass="0.41997427" diaginertia="0.00110455 0.00265592 0.00164653" />
            <joint name="left_joint_3" type="hinge" range="-0.8726646259971648 0.8726646259971648" axis="0 1 0" />
            <geom name="left_link_3_collision" type="mesh" mesh="left_link_3_collision_left_link_3" class="collision" />
            <geom name="left_link_3_visual" type="mesh" mesh="left_link_3_left_link_3" class="visual" />
            <body name="left_link_wheel" pos="0.22360679774998 -0.0368343791434203 -0.198990223087201">
              <inertial pos="-3.469e-17 -0.01158253 0.00017271" mass="2.32306566" diaginertia="0.00476729 0.0089701 0.00476823" />
              <joint name="left_joint_wheel" type="hinge" axis="0 1 0" />
              <geom name="left_link_wheel_collision" type="mesh" mesh="left_link_wheel_collision_left_link_wheel" class="collision" />
              <geom name="left_link_wheel_visual" type="mesh" mesh="left_link_wheel_left_link_wheel" class="visual" />
            </body>
          </body>
        </body>
      </body>
      <body name="right_link_1" pos="0.0689890658862278 0.123883478847376 -0.000994304172395266">
        <inertial pos="-0.0329313 0.0106322 0.0002716" mass="0.17414594" diaginertia="9.79354e-05 0.00018457 0.0001347" />
        <joint name="right_joint_1" type="hinge" range="-3.141592653589793 3.141592653589793" axis="1 0 0" />
        <geom name="right_link_1_collision" type="mesh" mesh="right_link_1_collision_right_link_1" class="collision" />
        <geom name="right_link_1_visual" type="mesh" mesh="right_link_1_right_link_1" class="visual" />
        <body name="right_link_2" pos="-0.0698 0.0195 0">
          <inertial pos="-0.1067452 -0.0104288 -0.0754200" mass="0.67262843" diaginertia="0.00196263 0.00341763 0.00227239" />
          <joint name="right_joint_2" type="hinge" range="0 2.0943951023931953" axis="0 1 0" />
          <geom name="right_link_2_collision" type="mesh" mesh="right_link_2_collision_right_link_2" class="collision" />
          <geom name="right_link_2_visual" type="mesh" mesh="right_link_2_right_link_2" class="visual" />
          <body name="right_link_3" pos="-0.223606797749979 -0.0150160895557946 -0.200246141172439">
            <inertial pos="0.0949942 0.0011798 -0.0810423" mass="0.41997427" diaginertia="0.00110455 0.00265592 0.00164653" />
            <joint name="right_joint_3" type="hinge" range="-0.8726646259971648 0.8726646259971648" axis="0 1 0" />
            <geom name="right_link_3_collision" type="mesh" mesh="right_link_3_collision_right_link_3" class="collision" />
            <geom name="right_link_3_visual" type="mesh" mesh="right_link_3_right_link_3" class="visual" />
            <body name="right_link_wheel" pos="0.22360679774998 0.0368343791434203 -0.198990223087201">
              <inertial pos="4.3368e-19 0.01158253 1.3878e-17" mass="2.32306566" diaginertia="0.00476729 0.00897104 0.00476729" />
              <joint name="right_joint_wheel" type="hinge" axis="0 1 0" />
              <geom name="right_link_wheel_collision" type="mesh" mesh="right_link_wheel_collision_right_link_wheel" class="collision" />
              <geom name="right_link_wheel_visual" type="mesh" mesh="right_link_wheel_right_link_wheel" class="visual" />
            </body>
          </body>
        </body>
      </body>
      <freejoint name="floating_base" />
    </body>
  </worldbody>
  <asset>
    <mesh name="base_link_collision_base_link" file="base_link.STL" />
    <mesh name="base_link_base_link" file="base_link.STL" />
    <mesh name="left_link_1_collision_left_link_1" file="left_link_1.STL" />
    <mesh name="left_link_1_left_link_1" file="left_link_1.STL" />
    <mesh name="left_link_2_collision_left_link_2" file="left_link_2.STL" />
    <mesh name="left_link_2_left_link_2" file="left_link_2.STL" />
    <mesh name="left_link_3_collision_left_link_3" file="left_link_3.STL" />
    <mesh name="left_link_3_left_link_3" file="left_link_3.STL" />
    <mesh name="left_link_wheel_collision_left_link_wheel" file="left_link_wheel.STL" />
    <mesh name="left_link_wheel_left_link_wheel" file="left_link_wheel.STL" />
    <mesh name="right_link_1_collision_right_link_1" file="right_link_1.STL" />
    <mesh name="right_link_1_right_link_1" file="right_link_1.STL" />
    <mesh name="right_link_2_collision_right_link_2" file="right_link_2.STL" />
    <mesh name="right_link_2_right_link_2" file="right_link_2.STL" />
    <mesh name="right_link_3_collision_right_link_3" file="right_link_3.STL" />
    <mesh name="right_link_3_right_link_3" file="right_link_3.STL" />
    <mesh name="right_link_wheel_collision_right_link_wheel" file="right_link_wheel.STL" />
    <mesh name="right_link_wheel_right_link_wheel" file="right_link_wheel.STL" />
  </asset>
  <actuator>
    <position name="left_joint_1" joint="left_joint_1" kp="30" />
    <position name="left_joint_2" joint="left_joint_2" kp="30" />
    <position name="left_joint_3" joint="left_joint_3" kp="30" />
    <position name="left_joint_wheel" joint="left_joint_wheel" kp="3" />
    <position name="right_joint_1" joint="right_joint_1" kp="30" />
    <position name="right_joint_2" joint="right_joint_2" kp="30" />
    <position name="right_joint_3" joint="right_joint_3" kp="30" />
    <position name="right_joint_wheel" joint="right_joint_wheel" kp="3" />
  </actuator>
  <sensor>
    <framelinvel name="local_linvel" objtype="body" objname="base_link" />
    <gyro name="gyro" site="imu_in_base" />
    <framezaxis name="upvector" objtype="body" objname="base_link" />
    <jointpos name="left_joint_1_pos" joint="left_joint_1" />
    <jointvel name="left_joint_1_vel" joint="left_joint_1" />
    <jointpos name="left_joint_2_pos" joint="left_joint_2" />
    <jointvel name="left_joint_2_vel" joint="left_joint_2" />
    <jointpos name="left_joint_3_pos" joint="left_joint_3" />
    <jointvel name="left_joint_3_vel" joint="left_joint_3" />
    <jointpos name="left_joint_wheel_pos" joint="left_joint_wheel" />
    <jointvel name="left_joint_wheel_vel" joint="left_joint_wheel" />
    <jointpos name="right_joint_1_pos" joint="right_joint_1" />
    <jointvel name="right_joint_1_vel" joint="right_joint_1" />
    <jointpos name="right_joint_2_pos" joint="right_joint_2" />
    <jointvel name="right_joint_2_vel" joint="right_joint_2" />
    <jointpos name="right_joint_3_pos" joint="right_joint_3" />
    <jointvel name="right_joint_3_vel" joint="right_joint_3" />
    <jointpos name="right_joint_wheel_pos" joint="right_joint_wheel" />
    <jointvel name="right_joint_wheel_vel" joint="right_joint_wheel" />
  </sensor>
</mujoco>
